Workbook

Sheet Sales Entry
A1: SALES ENTRY FORM — Investment Casting Quotation
A2: Sr | B2: Field | C2: Enter Value | D2: Hint / Example
A3: SECTION 1: Part Identification
A4: 1 | B4: Item Code | C4: 30D | D4: e.g. 30D
A5: 2 | B5: Die Code | C5: 30D | D5: same as Item Code usually
A6: 3 | B6: Plant | C6: Nasik | D6: Nasik / Mn
A7: 4 | B7: Date | C7: 16.09.2024 | D7: DD.MM.YYYY
A8: 5 | B8: Quotation No | C8: - | D8: Sales ref number
A9: 6 | B9: Customer Type | C9: Existing | D9: Existing / Prospective
A10: 7 | B10: Dom/Exp | C10: Domestic | D10: Domestic / Export
A11: 8 | B11: Customer Name | C11: DISCOM | D11: Full customer name
A12: 9 | B12: Supply Condition | C12: Machined | D12: Machined / UnMachined / Semi Finished
A13: 10 | B13: Part Description | C13: Down pipe Inlet casting | D13: As per drawing
A14: 11 | B14: Material Type | C14: MS | D14: MS / SS / Aluminium / Copper
A15: 12 | B15: Drw No | C15: 82909101 | D15: Drawing number
... A17: 14 | B17: UOM | C17: Nos | D17: Unit of Measure
A18: 15 | B18: Batch Qty | C18: 250000 | D18: Annual estimated qty
A19: SECTION 2: Composition — Min Values
A20: 1 | B20: Min C | C20: 0.25 | D20: Min % for C
A21: 2 | B21: Min Si | C21: 0.2 | D21: Min % for Si
A22: 3 | B22: Min Mn | C22: 0.7 | D22: Min % for Mn
A23: 4 | B23: Min P | C23: 0 | D23: Min % for P
A24: 5 | B24: Min S | C24: 0 | D24: Min % for S
A25: 6 | B25: Min Cr | C25: 0 | D25: Min % for Cr
A26: 7 | B26: Min Mo | C26: 0 | D26: Min % for Mo
A27: 8 | B27: Min Ni | C27: 0 | D27: Min % for Ni
A28: 9 | B28: Min Ti | C28: 0 | D28: Min % for Ti
A29: SECTION 2: Composition — Max Values
A30: 1 | B30: Max C | C30: 0.35 | D30: Max % for C
A31: 2 | B31: Max Si | C31: 1 | D31: Max % for Si
A32: 3 | B32: Max Mn | C32: 1 | D32: Max % for Mn
A33: 4 | B33: Max P | C33: 0.045 | D33: Max % for P
A34: 5 | B34: Max S | C34: 0.045 | D34: Max % for S
A35: 6 | B35: Max Cr | C35: 0.5 | D35: Max % for Cr
A36: 7 | B36: Max Mo | C36: 0.25 | D36: Max % for Mo
A37: 8 | B37: Max Ni | C37: 0.5 | D37: Max % for Ni
A38: 9 | B38: Max Ti | C38: 0 | D38: Max % for Ti
A39: SECTION 3: Mechanical Properties — Min
A40: 1 | B40: Min UTS | D40: Min value or blank
A41: 2 | B41: Min 0.2% PS/YS | D41: Min value or blank
...

Sheet Estimation Sheet
A1: Estimation
A2: Item Code | B2: ='Sales Entry'!C4 -> 30D | C2: Die Code | D2: ='Sales Entry'!C5 -> 30D | E2: Plant | F2: ='Sales Entry'!C6 -> Nasik | G2: Date : | H2: ='Sales Entry'!C7 -> 16.09.2024
A3: Quotation No | B3: ='Sales Entry'!C8 -> - | C3: Customer Type | D3: ='Sales Entry'!C9 -> Existing | E3: Dom/Exp | F3: ='Sales Entry'!C10 -> Domestic
A4: Customer Name | B4: ='Sales Entry'!C11 -> DISCOM | E4: Supply Condition | F4: ='Sales Entry'!C12 -> Machined
A5: Part Description | B5: ='Sales Entry'!C13 -> Down pipe Inlet casting | E5: Material Type | F5: ='Sales Entry'!C14 -> MS
A6: Drw No | B6: ='Sales Entry'!C15 -> 82909101 | E6: Material | F6: ='Sales Entry'!C16 -> ASTM A 732 2Q
A7: Part No | E7: UOM | F7: ='Sales Entry'!C17 -> Nos | G7: Batch Qty | H7: ='Sales Entry'!C18 -> 250000
A9: Composition
A10: Elements | B10: C | C10: Si | D10: Mn | E10: P | F10: S | G10: Cr | H10: Mo | I10: Ni | J10: Ti | K10: Cu
A11: Min | B11: ='Sales Entry'!C20 -> 0.25 | C11: ='Sales Entry'!C21 -> 0.2 | D11: ='Sales Entry'!C22 -> 0.7 | E11: ='Sales Entry'!C23 -> 0 | F11: ='Sales Entry'!C24 -> 0 | G11: ='Sales Entry'!C25 -> 0 | H11: ='Sales Entry'!C26 -> 0 | I11: ='Sales Entry'!C27 -> 0 | J11: ='Sales Entry'!C28 -> 0
A12: Max | B12: ='Sales Entry'!C30 -> 0.35 | C12: ='Sales Entry'!C31 -> 1 | D12: ='Sales Entry'!C32 -> 1 | E12: ='Sales Entry'!C33 -> 0.045 | F12: ='Sales Entry'!C34 -> 0.045 | G12: ='Sales Entry'!C35 -> 0.5 | H12: ='Sales Entry'!C36 -> 0.25 | I12: ='Sales Entry'!C37 -> 0.5 | J12: ='Sales Entry'!C38 -> 0
A13: Avg | B13: =IFERROR(AVERAGE(B11,B12),"") -> 0.3 | C13: =IFERROR(AVERAGE(C11,C12),"") -> 0.6 | D13: =IFERROR(AVERAGE(D11,D12),"") -> 0.85 | E13: =IFERROR(AVERAGE(E11,E12),"") -> 0.0225 | F13: =IFERROR(AVERAGE(F11,F12),"") -> 0.0225 | G13: =IFERROR(AVERAGE(G11,G12),"") -> 0.25 | H13: =IFERROR(AVERAGE(H11,H12),"") -> 0.125 | I13: =IFERROR(AVERAGE(I11,I12),"") -> 0.25 | J13: =IFERROR(AVERAGE(J11,J12),"") -> 0
A15: Charge Calculation
A16: Virgin Charge | H16: Return Charge
A17: Sr. No. | B17: Code | C17: Metal | D17: Rate | E17: Qty | F17: Value | H17: Sr. No. | I17: Code | J17: Metal | K17: Rate | L17: Qty | M17: Value
A18: 1 | F18: =E18*D18 -> 0 | H18: 1 | J18: Fe Si | K18: 117 | L18: 0.3 | M18: =L18*K18 -> 35.1
A19: 2 | F19: =E19*D19 -> 0 | H19: 6 | J19: Fe Cr 0.3% | K19: 268 | L19: 0.75 | M19: =L19*K19 -> 201
A20: 3 | F20: =E20*D20 -> 0 | H20: 3 | J20: Fe molly | K20: 2900 | L20: 0 | M20: =L20*K20 -> 0
A21: 4 | F21: =E21*D21 -> 0 | H21: 4 | J21: Pu Mn | K21: 177 | L21: 0.8 | M21: =L21*K21 -> 141.6
A22: 5 | F22: =E22*D22 -> 0 | H22: 5 | J22: Pu Ni | K22: 1550 | L22: 0 | M22: =L22*K22 -> 0
A23: 6 | F23: =E23*D23 -> 0 | H23: 6 | J23: Acti. Carbon | K23: 103 | L23: 0.1 | M23: =L23*K23 -> 10.3
A24: 7 | F24: =E24*D24 -> 0 | H24: 7 | J24: FeNb | K24: 3100 | L24: 0 | M24: =L24*K24 -> 0
A25: 8 | F25: =E25*D25 -> 0 | H25: 8 | J25: Nitrided Cr. | K25: 272 | L25: 0 | M25: =L25*K25 -> 0
A26: 9 | F26: =E26*D26 -> 0 | H26: 9 | J26: MSLC | K26: 45 | L26: 53 | M26: =L26*K26 -> 2385
A27: 10 | F27: =E27*D27 -> 0 | H27: 10 | J27: FeTi | K27: 168 | L27: 0 | M27: =L27*K27 -> 0
A28: 11 | F28: =E28*D28 -> 0 | H28: 11 | J28: C24 Return | K28: 56 | L28: 45.05 | M28: =L28*K28 -> 2522.8
A29: 12 | F29: =E29*D29 -> 0 | H29: 12 | M29: =L29*K29 -> 0
A30: Charge Rate (Virgin) | D30: =IFERROR(F30/E30,0) -> 0 | E30: =SUM(E18:E29) -> 0 | F30: =SUM(F18:F29) -> 0 | H30: Charge Rate (Return) | K30: =IFERROR(M30/L30,0) -> 52.958 | L30: =SUM(L18:L29) -> 100 | M30: =SUM(M18:M29) -> 5295.8
A32: Return Calculation | B32: Return Code | C32: Return Alloy Description | D32: Ret Alloy Rate | E32: Charge Rate | F32: Rate To Be considered
E33: =K30 -> 52.958 | F33: =IF(D33=0,E33,D33) -> 52.958
A35: Mechanical Properties
A36: Test | B36: UTS | C36: 0.2% PS/YS | D36: % Elong | E36: Impact | F36: R.A. | G36: Angle Of Bend
A37: Min | B37: ='Sales Entry'!C40 -> 0 | C37: ='Sales Entry'!C41 -> 0 | D37: ='Sales Entry'!C42 -> 0 | E37: ='Sales Entry'!C43 -> 0 | F37: ='Sales Entry'!C44 -> 0 | G37: ='Sales Entry'!C45 -> 0
A38: Max | B38: ='Sales Entry'!C47 -> 0 | C38: ='Sales Entry'!C48 -> 0 | D38: ='Sales Entry'!C49 -> 0 | E38: ='Sales Entry'!C50 -> 0 | F38: ='Sales Entry'!C51 -> 0 | G38: ='Sales Entry'!C52 -> 0
A40: Heat Treatment | B40: ='Sales Entry'!C54 -> Quenched & Tempered | E40: Surface Treatment | F40: ='Sales Entry'!C55 -> Oiling
A41: Hardness | B41: ='Sales Entry'!C56 -> 0
A42: Additional HT | B42: ='Sales Entry'!C57 -> 0 | E42: Inspection | F42: ='Sales Entry'!C58 -> UDL
A43: Additional Hardness | B43: ='Sales Entry'!C59 -> 0
B45: Value | E45: Wax | G45: Metal
A46: Qunatity | B46: =H7 -> 250000 | D46: Specific Gravity | E46: =VLOOKUP(E45,'Drop Downs'!A:B,2,0) -> 1.05 | G46: =VLOOKUP(F5,'Drop Downs'!A:B,2,0) -> 7.86
...

Sheet User Training
A1: USER TRAINING GUIDE — Estimation Template
A3: SECTION A: Getting Started — Workflow Steps
A4: Step 1 | B4: Open 'Sales Entry' sheet | C4: This is the ONLY sheet where you enter customer & part data
A5: Step 2 | B5: Fill all 7 sections in Sales Entry | C5: Item Code → Tooling Costs (69 fields total)
A6: Step 3 | B6: Switch to 'Estimation Sheet' | C6: All linked cells (GREEN) auto-populate from Sales Entry
A7: Step 4 | B7: Fill Charge Metals (Rows 18–28) | C7: Enter alloy metals, rates, quantities directly on Estimation Sheet
A8: Step 5 | B8: Fill Post-Foundry Operations (Rows 89–97) | C8: Enter fettling, finishing, HT, sandblasting rates
A9: Step 6 | B9: Fill Machining Operations (Rows 112–121) | C9: Enter cycle time, machine type, manual addon
A10: Step 7 | B10: Review BLUE formula cells | C10: These auto-calculate — DO NOT EDIT
A11: Step 8 | B11: Check final pricing (Rows 130–140) | C11: Verify Finished Casting Cost, Ex Price, Quoted Sales Price
A12: Step 9 | B12: Review Tooling (Rows 147–154) | C12: Auto-populated from Sales Entry Section 7
A13: Step 10 | B13: Print / Export for customer quotation | C13: Final review before sharing
A15: SECTION B: Color Legend — Estimation Sheet
A16: 🟢 GREEN | B16: Linked from Sales Entry | C16: Auto-filled — DO NOT type here. Edit in Sales Entry.
A17: 🔵 BLUE | B17: Formula / Auto-Calculated | C17: Computed by formulas — NEVER edit these cells.
A18: 🟡 YELLOW | B18: Direct Input on Est Sheet | C18: Enter directly (charge metals, post-foundry, machining).
A19: ⬜ WHITE | B19: Label / Header | C19: Static text — DO NOT modify.
A21: SECTION C: Field-by-Field Guide — Sales Entry (69 Fields)
A22: SECTION 1: Part Identification (15 fields)
B23: Item Code | C23: Unique code for the casting part | D23: Must match Die Code in most cases
B24: Die Code | C24: Wax injection die reference | D24: Used to track tooling
B25: Plant | C25: Manufacturing plant | D25: Nasik or Mn — drives different cost rates
B26: Date | C26: Quotation date | D26: Format: DD.MM.YYYY
B27: Quotation No | C27: Sales reference number | D27: Use '-' if not assigned yet
B28: Customer Type | C28: Existing or Prospective | D28: Affects pricing strategy
B29: Dom/Exp | C29: Domestic or Export | D29: Export uses foreign currency conversion
B30: Customer Name | C30: Full customer name | D30: As per PO / enquiry
B31: Supply Condition | C31: Machined / UnMachined / Semi Finished | D31: Drives machining cost section
B32: Part Description | C32: Part name as per drawing | D32: Be specific
B33: Material Type | C33: MS / SS / Aluminium / Copper | D33: Drives density, shell cost, overheads
B34: Drw No | C34: Drawing number | D34: Customer drawing reference
... B37: Batch Qty | C37: Annual estimated quantity | D37: Drives amortization of tooling
A38: SECTION 2: Composition (18 fields — 9 Min + 9 Max)
B39: Min/Max C, Si, Mn... | C39: Chemical composition range | D39: From material spec / customer drawing
B40: Avg (auto) | C40: Auto-calculated average
A41: SECTION 3: Mechanical Properties (12 fields — 6 Min + 6 Max)
B42: UTS | C42: Ultimate Tensile Strength | D42: In MPa or N/mm²
B43: 0.2% PS/YS | C43: Proof Stress / Yield Strength | D43: In MPa
B44: % Elong | C44: Percentage Elongation | D44: Ductility measure
B45: Impact | C45: Impact value (Charpy) | D45: In Joules
...

Sheet Drop Downs
A1: Material Type | B1: Density | C1: Customer Type | D1: Yes/No | E1: Additional HT | F1: Supply Condition | G1: Surface Treatment | H1: Heat Treatment | I1: Inspection | J1: Riser | K1: Riser Weight | L1: Geography | M1: Metal Code | N1: Metal | P1: Mechanical Prop | R1: Plant | S1: IH/OS | U1: Charge Type | W1: Machining Operations | X1: Machine Type | Y1: Machine Category | Z1: Post Foundry Operations | AA1: UOM of Operation
A2: MS | B2: 7.86 | C2: Existing | D2: Yes | E2: Induction Hardening | F2: Machined | G2: Pickling | H2: Annealing | I2: UDL | J2: Star Riser | K2: 4.021 | L2: Domestic | M2: C | N2: Carbon | P2: UTS | R2: Nasik | S2: IH | U2: Virgin | W2: Casting Machining | X2: EC 300 | Y2: HMC | Z2: Mould Fettling | AA2: MD
A3: SS | B3: 7.86 | C3: Prospective | D3: No | E3: Hardening & Tempering | F3: UnMachined | G3: Passivation | H3: Hardening | I3: Third Party | J3: 3V Full | K3: 1.8 | L3: Export | M3: Si | N3: Silicon | P3: 0.2% PS/YS | R3: Mn | S3: OS | U3: Return | W3: Casting Drilling | X3: EC 400 - 1 | Y3: HMC | Z3: Mould Finishing | AA3: MD
A4: Aluminium | B4: 2.7 | E4: Carburising | F4: Semi Finished | G4: Bath Nitrating | H4: Normalising | I4: Outsource | J4: 6T | K4: 1.9 | M4: Cr | N4: Chrome | P4: % Elong | W4: Casting Milling | X4: EC 400 - 2 | Y4: HMC | Z4: Casting Fettling | AA4: NO
A5: Wax | B5: 1.05 | E5: Hardening | G5: Electroplating | H5: Solution Annealing | J5: 5T spl+1 | K5: 1.8 | M5: Mn | N5: Mangenese | P5: Impact | W5: Casting Tapping | X5: VF 2 - 1 | Y5: VMC | Z5: Casting Sandblasting | AA5: NO
A6: Copper | B6: 8.9 | E6: Nitriding | G6: Oiling | H6: Tempering | J6: 5T-spl New | K6: 2.405 | M6: P | N6: Phosperous | P6: R.A. | W6: Casting Deburing | X6: VF 2 - 2 | Y6: VMC | Z6: Casting Rework | AA6: NO
G7: Sand Blast | H7: Case Carburising & Tempering | J7: 26E190 Riser | K7: 2.405 | M7: S | N7: Sulpher | P7: Angle Of Bend | W7: Induction Hardening | X7: VF 2 - 3 | Y7: VMC | Z7: Casting Pickling | AA7: KG
G8: SS.TUMBLAST & OILING | H8: Austempering | J8: 5T SPL Modified | K8: 2.004 | M8: Ni | N8: Nickel | X8: VF 2 - 4 | Y8: VMC | Z8: Casting Passivation | AA8: KG
G9: Pickling & Passivation | H9: Normalising & Tempering | J9: 29N01 | K9: 2.004 | M9: Cu | N9: Copper | X9: VF 2 - 5 | Y9: VMC | Z9: Casting Setting | AA9: NO
H10: Normalising, Case Carburizing & Tempering | J10: 1X117 MOD | K10: 2.405 | M10: Mo | X10: VF 4 - 1 | Y10: VMC | Z10: Casting Heat Treatment | AA10: KG
H11: Solution Annealing, Homogenization & Precipitation Hardening. | J11: V5 | K11: 1.807 | M11: N | X11: MAKINO 01 | Y11: MAKINO | Z11: Casting Induction Hardening | AA11: NO
H12: As cast | J12: Y SHAPE RISER | K12: 2 | M12: Ti | X12: MAKINO 02 | Y12: MAKINO | Z12: Casting Packing
H13: Quenched & Tempered | J13: Star Riser New | K13: 2.335 | X13: MAKINO 03 | Y13: MAKINO | Z13: Feed machining | AA13: No
H14: Normalising, Hardening & Tempering | J14: 8T | K14: 1.4 | X14: LMW 01 | Y14: LMW | Z14: Normalized OS | AA14: KG
J15: New Riser | K15: 1.2 | X15: LMW 02 | Y15: LMW | Z15: Hardening Tempering OS | AA15: KG
J16: 26E59 RISER | K16: 1.7 | X16: ACE SUPER JOBBER | Y16: ACE | Z16: Heat punching | AA16: NO
J17: NA | K17: 0 | X17: ACE JR 300-1 | Y17: ACE | Z17: Feed machining | AA17: No
J18: V5 Long | K18: 1.8 | X18: ACE JR 300-2 | Y18: ACE | Z18: Casting pressure testing | AA18: No
J19: 22F40 MODIFIED | K19: 2.16 | X19: VMC 350 - 1 | Y19: AMS VMC
J20: 7T | K20: 1.3 | X20: VMC 350 - 2 | Y20: AMS VMC
X21: VMC 350 - 3 | Y21: AMS VMC
X22: VMC 400 - 1 | Y22: AMS VMC

Sheet Machine Shop Rates
A2: Machine Name | B2: Machine Type | C2: Machine Description | D2: Labour | E2: Power | F2: Depreciation | G2: Consumables | H2: Maintenance | I2: Maintenance Spares | J2: AMC Cost | K2: Any Other Cost | L2: Total | M2: Total M/c Hours Available | N2: Rate / Hr
A3: EC 300 | B3: HMC | D3: =105*22*26*12 -> 720720 | L3: =SUM(D3:K3) -> 720720 | M3: =22*26*12 -> 6864 | N3: =L3/M3 -> 105 | O3: =M3*N3 -> 720720
A4: EC 400 - 1 | B4: HMC | D4: =105*22*26*12 -> 720720 | L4: =SUM(D4:K4) -> 720720 | M4: =22*26*12 -> 6864 | N4: =L4/M4 -> 105
A5: EC 400 - 2 | B5: HMC | D5: =105*22*26*12 -> 720720 | L5: =SUM(D5:K5) -> 720720 | M5: =22*26*12 -> 6864 | N5: =L5/M5 -> 105
A6: VF 2 - 1 | B6: VMC | D6: =105*22*26*12 -> 720720 | L6: =SUM(D6:K6) -> 720720 | M6: =22*26*12 -> 6864 | N6: =L6/M6 -> 105
A7: VF 2 - 2 | B7: VMC | D7: =105*22*26*12 -> 720720 | L7: =SUM(D7:K7) -> 720720 | M7: =22*26*12 -> 6864 | N7: =L7/M7 -> 105
A8: VF 2 - 3 | B8: VMC | D8: =105*22*26*12 -> 720720 | L8: =SUM(D8:K8) -> 720720 | M8: =22*26*12 -> 6864 | N8: =L8/M8 -> 105
A9: VF 2 - 4 | B9: VMC | D9: =105*22*26*12 -> 720720 | L9: =SUM(D9:K9) -> 720720 | M9: =22*26*12 -> 6864 | N9: =L9/M9 -> 105
A10: VF 2 - 5 | B10: VMC | D10: =105*22*26*12 -> 720720 | L10: =SUM(D10:K10) -> 720720 | M10: =22*26*12 -> 6864 | N10: =L10/M10 -> 105
A11: VF 4 - 1 | B11: VMC | D11: =105*22*26*12 -> 720720 | L11: =SUM(D11:K11) -> 720720 | M11: =22*26*12 -> 6864 | N11: =L11/M11 -> 105
A12: MAKINO 01 | B12: MAKINO | D12: =105*22*26*12 -> 720720 | L12: =SUM(D12:K12) -> 720720 | M12: =22*26*12 -> 6864 | N12: =L12/M12 -> 105
A13: MAKINO 02 | B13: MAKINO | D13: =105*22*26*12 -> 720720 | L13: =SUM(D13:K13) -> 720720 | M13: =22*26*12 -> 6864 | N13: =L13/M13 -> 105
A14: MAKINO 03 | B14: MAKINO | D14: =105*22*26*12 -> 720720 | L14: =SUM(D14:K14) -> 720720 | M14: =22*26*12 -> 6864 | N14: =L14/M14 -> 105
A15: LMW 01 | B15: LMW | D15: =105*22*26*12 -> 720720 | L15: =SUM(D15:K15) -> 720720 | M15: =22*26*12 -> 6864 | N15: =L15/M15 -> 105
... A23: VMC 400 - 1 | B23: AMS VMC | D23: =105*22*26*12 -> 720720 | L23: =SUM(D23:K23) -> 720720 | M23: =22*26*12 -> 6864 | N23: =L23/M23 -> 105

Sheet Sheet1
A1: Sr. No. | B1: Machine | C1: Type | D1: Make | E1: Qty | F1: Kw Each per Hour | G1: KW Total per Hour
A2: 1 | B2: EC- 400 /300 | C2: HMC | D2: HAAS | E2: 3 | F2: 19 | G2: 57
A3: 2 | B3: VF - 2 | C3: VMC | D3: HAAS | E3: 4 | F3: 19 | G3: 76
A4: 3 | B4: VF- 2 I & VF - 4 I | C4: VMC | D4: HAAS | E4: 1 | F4: 18 | G4: 18
A5: 4 | B5: Makino Slim -3 | C5: VMC | D5: Makino | E5: 3 | F5: 24 | G5: 72
A6: 5 | B6: LMW | C6: Turning Center | D6: LMW | E6: 2 | F6: 12 | G6: 24
A7: 6 | B7: MCV -350 | C7: VMC | D7: ACE | E7: 3 | F7: 18 | G7: 55
A8: 7 | B8: MCV -400 | C8: VMC | D8: ACE | E8: 1 | F8: 22 | G8: 22
A9: 8 | B9: Super Jobber | C9: Turning Center | D9: ACE | E9: 1 | F9: 17 | G9: 17
A10: 9 | B10: Junior Jobber | C10: Turning Center | D10: ACE | E10: 1 | F10: 13 | G10: 13
A11: 10 | B11: J300 LM | C11: Turning Center | D11: ACE | E11: 1 | F11: 11 | G11: 11
F12: Total KW | G12: 366
B14: Utility | C14: Type | D14: Make | E14: Qty | F14: Kw Each | G14: KW Total
A15: 1 | B15: Air Compressor | C15: Screw | D15: Atlas Copco | E15: 1 | F15: 12 | G15: 12
A16: 2 | B16: Illumination | C16: T/Lights | D16: Phillips | E16: 40 | F16: 0.8 | G16: 32
A17: 3 | B17: AC (5.5TR x 6Nos) | C17: Ductable split | D17: Voltas | E17: 6 | F17: 14 | G17: 86
F18: Total KW | G18: 130

Sheet Wax Shell Rate
A1: Shell Rate | B1: Nasik | C1: Nasik | D1: Mn | G1: 20300STR | M1: 20200STR
A2: Shell Rate | B2: MS | C2: SS | G2: Pattern Batch Regular KG | H2: Erp Code | I2: Qty | J2: Rate | K2: Value | M2: Pattern Batch Regular KG | N2: Erp Code | O2: Qty | P2: Rate | Q2: Value
A3: 20300STR | C3: =SUMIFS('Nasik Ledger'!N:N,'Nasik Ledger'!$A:$A,$A3,'Nasik Ledger'!$I:$I,"RMSL")+SUMIFS('Nasik Ledger'!P:P,'Nasik Ledger'!$A:$A,$A3,'Nasik Ledger'!$I:$I,"RMSL")+SUMIFS('Nasik Ledger'!N:N,'Nasik Ledger'!$A:$A,$A3,'Nasik Ledger'!$I:$I,"RMSI")+SUMIFS('Nasik Ledger'!P:P,'Nasik Ledger'!$A:$A,$A3,'Nasik Ledger'!$I:$I,"RMSI") -> -1894072.4 | D3: =SUMIFS('Nasik Ledger'!O:O,'Nasik Ledger'!$A:$A,$A3,'Nasik Ledger'!$I:$I,"RMSL")+SUMIFS('Nasik Ledger'!Q:Q,'Nasik Ledger'!$A:$A,$A3,'Nasik Ledger'!$I:$I,"RMSL")+SUMIFS('Nasik Ledger'!O:O,'Nasik Ledger'!$A:$A,$A3,'Nasik Ledger'!$I:$I,"RMSI")+SUMIFS('Nasik Ledger'!Q:Q,'Nasik Ledger'!$A:$A,$A3,'Nasik Ledger'!$I:$I,"RMSI") -> -59107117 | E3: 49 | G3: RD053 | H3: 0111014 | I3: 24 | J3: =VLOOKUP(CONCATENATE("'",$H3),'Nasik Ledger'!$F$3:$AB$957,21,0) -> 163.62033 | K3: =J3*I3 -> 3926.8879 | M3: RD053 | N3: 0111014 | O3: 24 | P3: =VLOOKUP(CONCATENATE("'",$N3),'Mn Ledger'!$F$3:$AB$957,21,0) -> 163.66812 | Q3: =P3*O3 -> 3928.0349
A4: 20200STR | C4: =SUMIFS('Mn Ledger'!N:N,'Mn Ledger'!$A:$A,$A4,'Mn Ledger'!$I:$I,"RMSL")+SUMIFS('Mn Ledger'!P:P,'Mn Ledger'!$A:$A,$A4,'Mn Ledger'!$I:$I,"RMSL")+SUMIFS('Mn Ledger'!N:N,'Mn Ledger'!$A:$A,$A4,'Mn Ledger'!$I:$I,"RMSI")+SUMIFS('Mn Ledger'!P:P,'Mn Ledger'!$A:$A,$A4,'Mn Ledger'!$I:$I,"RMSI") -> -1041637.5 | D4: =SUMIFS('Mn Ledger'!O:O,'Mn Ledger'!$A:$A,$A4,'Mn Ledger'!$I:$I,"RMSL")+SUMIFS('Mn Ledger'!Q:Q,'Mn Ledger'!$A:$A,$A4,'Mn Ledger'!$I:$I,"RMSL")+SUMIFS('Mn Ledger'!O:O,'Mn Ledger'!$A:$A,$A4,'Mn Ledger'!$I:$I,"RMSI")+SUMIFS('Mn Ledger'!Q:Q,'Mn Ledger'!$A:$A,$A4,'Mn Ledger'!$I:$I,"RMSI") -> -42056205 | E4: =D4/C4 -> 40.375087 | G4: RD001 | H4: 0111001 | I4: 3 | J4: =VLOOKUP(CONCATENATE("'",$H4),'Nasik Ledger'!$F$3:$AB$957,21,0) -> 129.21989 | K4: =J4*I4 -> 387.65966 | M4: RD001 | N4: 0111001 | O4: 3 | P4: =VLOOKUP(CONCATENATE("'",$N4),'Mn Ledger'!$F$3:$AB$957,21,0) -> 134.45535 | Q4: =P4*O4 -> 403.36605 | T4: To calculate Overhead for Wax
G5: RD020 | H5: 0111006 | I5: 2.5 | J5: =VLOOKUP(CONCATENATE("'",$H5),'Nasik Ledger'!$F$3:$AB$957,21,0) -> 420.34669 | K5: =J5*I5 -> 1050.8667 | M5: RD020 | N5: 0111006 | O5: 2.5 | P5: =VLOOKUP(CONCATENATE("'",$N5),'Mn Ledger'!$F$3:$AB$957,21,0) -> 420.64602 | Q5: =P5*O5 -> 1051.615 | T5: 1. Labour required
A6: Pattern Wax | B6: 81.79 | C6: 81.79 | D6: 81.81 | G6: RD105 | H6: 0111052 | I6: 2 | J6: =VLOOKUP(CONCATENATE("'",$H6),'Nasik Ledger'!$F$3:$AB$957,21,0) -> 497.22059 | K6: =J6*I6 -> 994.44117 | M6: RD105 | N6: 0111052 | O6: 2 | P6: =VLOOKUP(CONCATENATE("'",$N6),'Mn Ledger'!$F$3:$AB$957,21,0) -> 494.81074 | Q6: =P6*O6 -> 989.62149 | T6: 2. Power Required
A7: Riser Wax | B7: 13.88 | C7: 13.88 | D7: 13.82 | G7: RD011 | H7: 0111004 | I7: 1.5 | J7: =VLOOKUP(CONCATENATE("'",$H7),'Nasik Ledger'!$F$3:$AB$957,21,0) -> 126.95901 | K7: =J7*I7 -> 190.43851 | M7: RD011 | N7: 0111004 | O7: 1.5 | P7: =VLOOKUP(CONCATENATE("'",$N7),'Mn Ledger'!$F$3:$AB$957,21,0) -> 123.61997 | Q7: =P7*O7 -> 185.42996 | T7: 3. Depreciation
A8: Water Sol Wax | B8: 70 | C8: 70 | D8: 70 | G8: Reclaimed Wax | I8: 137 | J8: =J38 -> 7.3208557 | K8: =J8*I8 -> 1002.9572 | M8: Reclaimed Wax | O8: 137 | P8: =P38 -> 7.3215336 | Q8: =P8*O8 -> 1003.0501
A9: Ceramic Core | B9: 400 | C9: 400 | D9: 400 | G9: RD072/RD304 | H9: 0111022 | I9: 30 | J9: =VLOOKUP(CONCATENATE("'",$H9),'Nasik Ledger'!$F$3:$AB$957,21,0) -> 210 | K9: =J9*I9 -> 6300 | M9: RD072/RD304 | N9: 0111022 | O9: 30 | P9: =VLOOKUP(CONCATENATE("'",$N9),'Mn Ledger'!$F$3:$AB$957,21,0) -> 210 | Q9: =P9*O9 -> 6299.9999
A10: Shell Cost | B10: 42 | C10: 45 | D10: 39 | G10: Overhead | I10: 200 | J10: 10 | K10: =J10*I10 -> 2000 | M10: Overhead | O10: 200 | P10: 10 | Q10: =P10*O10 -> 2000
G11: Total | I11: 200 | J11: =K11/I11 -> 79.266256 | K11: =SUM(K3:K10) -> 15853.251 | M11: Total | O11: 200 | P11: =Q11/O11 -> 79.305587 | Q11: =SUM(Q3:Q10) -> 15861.117
A12: For 3M | B12: 120 | C12: Only for specific codes - Spinner, Impeller
G13: Pattern Batch 26E serries KG | M13: Pattern Batch 26E serries KG
G14: RD053 | H14: 0111014 | I14: 11.9 | J14: =VLOOKUP(CONCATENATE("'",$H14),'Nasik Ledger'!$F$3:$AB$957,21,0) -> 163.62033 | K14: =J14*I14 -> 1947.0819 | M14: RD053 | N14: 0111014 | O14: 11.9 | P14: =VLOOKUP(CONCATENATE("'",$N14),'Mn Ledger'!$F$3:$AB$957,21,0) -> 163.66812 | Q14: =P14*O14 -> 1947.6506
G15: RD001 | H15: 0111001 | I15: 2.45 | J15: =VLOOKUP(CONCATENATE("'",$H15),'Nasik Ledger'!$F$3:$AB$957,21,0) -> 129.21989 | K15: =J15*I15 -> 316.58873 | M15: RD001 | N15: 0111001 | O15: 2.45 | P15: =VLOOKUP(CONCATENATE("'",$N15),'Mn Ledger'!$F$3:$AB$957,21,0) -> 134.45535 | Q15: =P15*O15 -> 329.41561
G16: RD020 | H16: 0111006 | I16: 1.4 | J16: =VLOOKUP(CONCATENATE("'",$H16),'Nasik Ledger'!$F$3:$AB$957,21,0) -> 420.34669 | K16: =J16*I16 -> 588.48537 | M16: RD020 | N16: 0111006 | O16: 1.4 | P16: =VLOOKUP(CONCATENATE("'",$N16),'Mn Ledger'!$F$3:$AB$957,21,0) -> 420.64602 | Q16: =P16*O16 -> 588.90442
G17: RD105 | H17: 0111052 | I17: 1.05 | J17: =VLOOKUP(CONCATENATE("'",$H17),'Nasik Ledger'!$F$3:$AB$957,21,0) -> 497.22059 | K17: =J17*I17 -> 522.08161 | M17: RD105 | N17: 0111052 | O17: 1.05 | P17: =VLOOKUP(CONCATENATE("'",$N17),'Mn Ledger'!$F$3:$AB$957,21,0) -> 494.81074 | Q17: =P17*O17 -> 519.55128
G18: RD011 | H18: 0111004 | I18: 0.7 | J18: =VLOOKUP(CONCATENATE("'",$H18),'Nasik Ledger'!$F$3:$AB$957,21,0) -> 126.95901 | K18: =J18*I18 -> 88.871306 | M18: RD011 | N18: 0111004 | O18: 0.7 | P18: =VLOOKUP(CONCATENATE("'",$N18),'Mn Ledger'!$F$3:$AB$957,21,0) -> 123.61997 | Q18: =P18*O18 -> 86.533982
G19: Reclaimed Wax | I19: 57.5 | J19: =J38 -> 7.3208557 | K19: =J19*I19 -> 420.9492 | M19: Reclaimed Wax | O19: 57.5 | P19: =P38 -> 7.3215336 | Q19: =P19*O19 -> 420.98818
G20: RD072 | H20: 0111022 | I20: 15 | J20: =VLOOKUP(CONCATENATE("'",$H20),'Nasik Ledger'!$F$3:$AB$957,21,0) -> 210 | K20: =J20*I20 -> 3150 | M20: RD072 | N20: 0111022 | O20: 15 | P20: =VLOOKUP(CONCATENATE("'",$N20),'Mn Ledger'!$F$3:$AB$957,21,0) -> 210 | Q20: =P20*O20 -> 3149.9999
G21: RD 304 | H21: 0111073 | I21: 10 | J21: 210 | K21: =J21*I21 -> 2100 | M21: RD 304 | N21: 0111073 | O21: 10 | P21: 210 | Q21: =P21*O21 -> 2100
G22: Overhead | I22: 100 | J22: 10 | K22: =J22*I22 -> 1000 | M22: Overhead | O22: 100 | P22: 10 | Q22: =P22*O22 -> 1000
G23: TOTAL | I23: 100 | J23: =K23/I23 -> 101.34058 | K23: =SUM(K14:K22) -> 10134.058 | M23: TOTAL | O23: 100 | P23: =Q23/O23 -> 101.43044 | Q23: =SUM(Q14:Q22) -> 10143.044
G25: Riser Batch KG | M25: Riser Batch KG
G26: RECLAIM WAX | I26: 80 | J26: =J38 -> 7.3208557 | K26: =J26*I26 -> 585.66846 | M26: RECLAIM WAX | O26: 80 | P26: =P38 -> 7.3215336 | Q26: =P26*O26 -> 585.72269
G27: FILTER WAX | I27: 60 | J27: 0 | K27: 0 | M27: FILTER WAX | O27: 60 | P27: 0 | Q27: =P27*O27 -> 0
G28: RD 001 | H28: 0111001 | I28: 3 | J28: =VLOOKUP(CONCATENATE("'",$H28),'Nasik Ledger'!$F$3:$AB$957,21,0) -> 129.21989 | K28: =J28*I28 -> 387.65966 | M28: RD 001 | N28: 0111001 | O28: 3 | P28: =VLOOKUP(CONCATENATE("'",$N28),'Mn Ledger'!$F$3:$AB$957,21,0) -> 134.45535 | Q28: =P28*O28 -> 403.36605
G29: RD 011 | H29: 0111004 | I29: 2 | J29: =VLOOKUP(CONCATENATE("'",$H29),'Nasik Ledger'!$F$3:$AB$957,21,0) -> 126.95901 | K29: =J29*I29 -> 253.91802 | M29: RD 011 | N29: 0111004 | O29: 2 | P29: =VLOOKUP(CONCATENATE("'",$N29),'Mn Ledger'!$F$3:$AB$957,21,0) -> 123.61997 | Q29: =P29*O29 -> 247.23995
G30: Overhead | I30: 145 | J30: 5 | K30: =J30*I30 -> 725 | M30: Overhead | O30: 145 | P30: 5 | Q30: =P30*O30 -> 725
G31: TOTAL | I31: 145 | J31: =K31/I31 -> 13.463766 | K31: =SUM(K26:K30) -> 1952.2461 | M31: TOTAL | O31: 145 | P31: =Q31/O31 -> 13.526405 | Q31: =SUM(Q26:Q30) -> 1961.3287
G34: Reclaim Batch Kg | M34: Reclaim Batch Kg
G35: SETTELED WAX/FILTERED WAX | I35: 139 | J35: 0 | K35: 0 | M35: SETTELED WAX/FILTERED WAX | O35: 139 | P35: 0 | Q35: 0
G36: RD053 | H36: 0111014 | I36: 2 | J36: =VLOOKUP(CONCATENATE("'",$H36),'Nasik Ledger'!$F$3:$AB$957,21,0) -> 163.62033 | K36: =J36*I36 -> 327.24066 | M36: RD053 | N36: 0111014 | O36: 2 | P36: =VLOOKUP(CONCATENATE("'",$N36),'Mn Ledger'!$F$3:$AB$957,21,0) -> 163.66812 | Q36: =P36*O36 -> 327.33624
G37: Overhead | I37: 141 | J37: 5 | K37: =J37*I37 -> 705 | M37: Overhead | O37: 141 | P37: 5 | Q37: =P37*O37 -> 705
G38: TOTAL | I38: 141 | J38: =K38/I38 -> 7.3208557 | K38: =SUM(K35:K37) -> 1032.2407 | M38: TOTAL | O38: 141 | P38: =Q38/O38 -> 7.3215336 | Q38: =SUM(Q35:Q37) -> 1032.3362

Sheet Testing Charges Calculations
A1: Chemical Analysis | C1: Labour
A2: Tensile Test | C2: Power
A3: Impact Test | C3: Depreciation
A4: Bend Test | C4: Consumables
A5: Metallography | C5: Maintenance
A6: IGCT | C6: Maintenance Spares
A7: LP/DP | C7: Overhead
A8: Magnetic Particle
A9: Radiography
A10: Any Other

Sheet Exchange Rate
A1: Curr | B1: Rate
A2: USD | B2: 82.46
A3: GBP | B3: 91
A4: EUR | B4: 81.22
A5: INR | B5: 1

Sheet Master
B1: Mn | C1: Nasik | D1: Nasik | E1: UOM | I1: Avg Std Mld Wt
C2: MS | D2: SS
A3: Overhead | B3: 389 | C3: 1621.88 | D3: 1696.12 | E3: Per Mould | H3: Nasik | I3: 27 | J3: Mould Wt in Kg
A4: Labour | B4: 537 | C4: 488 | D4: 488 | E4: Per Mould | H4: Mn | I4: 23 | J4: Mould Wt in Kg
A5: Heat Treatment | B5: 0 | C5: 0 | D5: 0 | E5: Actual
A6: Consumables | B6: 319 | C6: 645.02 | D6: 706.98 | E6: Per Mould
A7: Power | B7: 24 | C7: 26 | D7: 26 | E7: Per Kg
A8: Fuel | E8: Per Mould
A9: Meting Loss | B9: 0.03 | C9: 0.03 | D9: 0.03 | E9: Percentage
A10: Margin % | B10: 0 | C10: =B10 -> 0 | D10: =B10 -> 0 | E10: Enter in % e.g. for 13 % enter "13%"
A11: Metal Rate Fluctuation | B11: 0 | C11: 0 | D11: 0 | E11: Percentage
A28: Machine Shop | B28: Total Amount | C28: Per Hr Rate
A29: Labour | B29: =9956434+6500000 -> 16456434 | C29: =B29/$B$35 -> 123.5635
A30: Power | B30: 3539178 | C30: =B30/$B$35 -> 26.573996
A31: Consumables | B31: 6075345 | C31: =B31/$B$35 -> 45.616863
A35: Time Available | B35: =21*302*21 -> 133182
A37: Machine Type | B37: Rate / Hr
A38: HMC | B38: 1000
A39: VMC | B39: 650
A40: MAKINO | B40: 600
A41: LMW | B41: 180
A42: ACE | B42: 180
A43: AMS VMC | B43: 480

Sheet Nasik Ledger
I1: B/p GL | J1: Opening Stock | K1: Opening Stock | L1: RECEIPT | M1: RECEIPT | N1: SIR | O1: SIR | P1: IGR | Q1: IGR | R1: SALES | S1: SALES | T1: TRASNFER | U1: TRASNFER | V1: Other Tran | W1: Other Tran | X1: Closing Stock | Y1: Closing Stock
A2: Branch Plant | B2: From Date | C2: To Date | D2: From Date | E2: To Date | F2: Item Code | G2: Description | H2: UOM | I2: Code | J2: Qty | K2: Amount | L2: Qty | M2: Amount | N2: Qty | O2: Amount | P2: Qty | Q2: Amount | R2: Qty | S2: Amount | T2: Qty | U2: Amount | V2: Qty | W2: Amount | X2: Qty | Y2: Amount | Z2: Rate
A3: 20300STR | B3: 44287 | C3: 44651 | D3: 20210401 | E3: 20220331 | F3: '001T0128D | G3: 1T128 FOUR CAVITY WAX INJ. | H3: NO | I3: TLL | P3: 1 | R3: -1 | Z3: =IFERROR((O3+Q3)/(N3+P3),Y3/X3) -> 0
A4: 20300STR | B4: 44287 | C4: 44651 | D4: 20210401 | E4: 20220331 | F4: '001T0155D | G4: 1T155 FOUR CAVITY WAX INJE. | H4: NO | I4: TLL | P4: 1 | Q4: 111000 | R4: -1 | S4: -111000 | Z4: =IFERROR((O4+Q4)/(N4+P4),Y4/X4) -> 111000
A5: 20300STR | B5: 44287 | C5: 44651 | D5: 20210401 | E5: 20220331 | F5: '001T0156D | G5: 1T156 FOUR CAVITY WAX MOULD | H5: NO | I5: TLL | P5: 1 | R5: -1 | Z5: =IFERROR((O5+Q5)/(N5+P5),Y5/X5) -> 0
A6: 20300STR | B6: 44287 | C6: 44651 | D6: 20210401 | E6: 20220331 | F6: '001T0162D | G6: 1T162 FOUR CAVITY WAX INJE. | H6: NO | I6: TLL | L6: 1 | M6: 110000 | N6: -1 | O6: -110000 | P6: 1 | Q6: 110000 | R6: -1 | S6: -110000 | Z6: =IFERROR((O6+Q6)/(N6+P6),Y6/X6) -> #DIV/0!
A7: 20300STR | B7: 44287 | C7: 44651 | D7: 20210401 | E7: 20220331 | F7: '001T0165D | G7: 1T165/138 TWO CAVITY WAX INJ. | H7: NO | I7: TLL | P7: 1 | R7: -1 | Z7: =IFERROR((O7+Q7)/(N7+P7),Y7/X7) -> 0
A8: 20300STR | B8: 44287 | C8: 44651 | D8: 20210401 | E8: 20220331 | F8: '001T0196D | G8: 1T196 TWO CAVITY WAX INJ.MOULD | H8: NO | I8: TLL | L8: 1 | M8: 220000 | N8: -1 | O8: -220000 | Z8: =IFERROR((O8+Q8)/(N8+P8),Y8/X8) -> 220000
A9: 20300STR | B9: 44287 | C9: 44651 | D9: 20210401 | E9: 20220331 | F9: '001T0199D | G9: 1T199 TWO CAVITY WAX INJECTION | H9: NO | I9: TLL | P9: 1 | R9: -1 | Z9: =IFERROR((O9+Q9)/(N9+P9),Y9/X9) -> 0
A10: 20300STR | B10: 44287 | C10: 44651 | D10: 20210401 | E10: 20220331 | F10: '001T0200D | G10: 1T200 TWO CAVITY WAX INJ. DIE | H10: NO | I10: TLL | P10: 1 | Q10: 95450 | R10: -1 | S10: -95450 | Z10: =IFERROR((O10+Q10)/(N10+P10),Y10/X10) -> 95450
A11: 20300STR | B11: 44287 | C11: 44651 | D11: 20210401 | E11: 20220331 | F11: '001T0203D | G11: 1T203 TWO CAVITY WAX INJECTION | H11: NO | I11: TLL | P11: 1 | Q11: 100729 | R11: -1 | S11: -100729 | Z11: =IFERROR((O11+Q11)/(N11+P11),Y11/X11) -> 100729
A12: 20300STR | B12: 44287 | C12: 44651 | D12: 20210401 | E12: 20220331 | F12: '001T0204D | G12: 1T204 TWO CAVITY WAX INJECTION | H12: NO | I12: TLL | P12: 1 | Q12: 101971 | R12: -1 | S12: -101971 | Z12: =IFERROR((O12+Q12)/(N12+P12),Y12/X12) -> 101971
A13: 20300STR | B13: 44287 | C13: 44651 | D13: 20210401 | E13: 20220331 | F13: '001T0205D | G13: 1T205 TWO CAVITY WAX INJECTION | H13: NO | I13: TLL | P13: 1 | Q13: 92541 | R13: -1 | S13: -92541 | Z13: =IFERROR((O13+Q13)/(N13+P13),Y13/X13) -> 92541
A14: 20300STR | B14: 44287 | C14: 44651 | D14: 20210401 | E14: 20220331 | F14: '001T0210D | G14: 1T210 SINGLE CAVITY WAX INJ. | H14: NO | I14: TLL | P14: 1 | Q14: 110000 | R14: -1 | S14: -110000 | Z14: =IFERROR((O14+Q14)/(N14+P14),Y14/X14) -> 110000
A15: 20300STR | B15: 44287 | C15: 44651 | D15: 20210401 | E15: 20220331 | F15: '001T0210RD | G15: 1T210 RISER MOULD WITH | H15: NO | I15: TLL | P15: 1 | Q15: 42000 | R15: -1 | S15: -42000 | Z15: =IFERROR((O15+Q15)/(N15+P15),Y15/X15) -> 42000
A16: 20300STR | B16: 44287 | C16: 44651 | D16: 20210401 | E16: 20220331 | F16: '001T0213D | G16: 1T213 TWO CAVITY WAX INJECTION | H16: NO | I16: TLL | P16: 1 | Q16: 65000 | R16: -1 | S16: -65000 | Z16: =IFERROR((O16+Q16)/(N16+P16),Y16/X16) -> 65000
A17: 20300STR | B17: 44287 | C17: 44651 | D17: 20210401 | E17: 20220331 | F17: '001T0214D | G17: 1T214 TWO CAVITY WAX INJECTION | H17: NO | I17: TLL | P17: 1 | Q17: 78000 | R17: -1 | S17: -78000 | Z17: =IFERROR((O17+Q17)/(N17+P17),Y17/X17) -> 78000
A18: 20300STR | B18: 44287 | C18: 44651 | D18: 20210401 | E18: 20220331 | F18: '001TC207 | G18: CERAMIC CORE 2T207 | H18: NO | I18: CONS | K18: 0.01 | L18: 41139 | M18: 1439865 | N18: -41139 | O18: -1439865 | Y18: 0.01 | Z18: =IFERROR((O18+Q18)/(N18+P18),Y18/X18) -> 35
A19: 20300STR | B19: 44287 | C19: 44651 | D19: 20210401 | E19: 20220331 | F19: '002T0040D | G19: 2T40 MAIN DIE | H19: NO | I19: TLL | P19: 1 | Q19: 77000 | R19: -1 | S19: -77000 | Z19: =IFERROR((O19+Q19)/(N19+P19),Y19/X19) -> 77000
A20: 20300STR | B20: 44287 | C20: 44651 | D20: 20210401 | E20: 20220331 | F20: '002T0052D | G20: 2T52 TWO CAVITY WAX MOULD | H20: NO | I20: TLL | P20: 1 | R20: -1 | Z20: =IFERROR((O20+Q20)/(N20+P20),Y20/X20) -> 0
A21: 20300STR | B21: 44287 | C21: 44651 | D21: 20210401 | E21: 20220331 | F21: '002T0053D | G21: 2T53 TWO CAVITY WAX MOULD | H21: NO | I21: TLL | P21: 1 | R21: -1 | Z21: =IFERROR((O21+Q21)/(N21+P21),Y21/X21) -> 0
A22: 20300STR | B22: 44287 | C22: 44651 | D22: 20210401 | E22: 20220331 | F22: '002T0054D | G22: 2T54 TWO CAVITY WAX MOULD | H22: NO | I22: TLL | P22: 1 | R22: -1 | Z22: =IFERROR((O22+Q22)/(N22+P22),Y22/X22) -> 0
A23: 20300STR | B23: 44287 | C23: 44651 | D23: 20210401 | E23: 20220331 | F23: '002T0055D | G23: 2T55 TWO CAVITY WAX MOULD | H23: NO | I23: TLL | P23: 1 | R23: -1 | Z23: =IFERROR((O23+Q23)/(N23+P23),Y23/X23) -> 0
A24: 20300STR | B24: 44287 | C24: 44651 | D24: 20210401 | E24: 20220331 | F24: '002T0056D | G24: 2T56 TWO CAVITY WAX MOULD | H24: NO | I24: TLL | P24: 1 | R24: -1 | Z24: =IFERROR((O24+Q24)/(N24+P24),Y24/X24) -> 0
A25: 20300STR | B25: 44287 | C25: 44651 | D25: 20210401 | E25: 20220331 | F25: '002T0057CD | G25: 2T57 TWO CAVITY WAX CHILL | H25: NO | I25: TLL | P25: 1 | R25: -1 | Z25: =IFERROR((O25+Q25)/(N25+P25),Y25/X25) -> 0
A26: 20300STR | B26: 44287 | C26: 44651 | D26: 20210401 | E26: 20220331 | F26: '002T0057D | G26: 2T57 TWO CAVITY WAX MAIN | H26: NO | I26: TLL | P26: 1 | R26: -1 | Z26: =IFERROR((O26+Q26)/(N26+P26),Y26/X26) -> 0
A27: 20300STR | B27: 44287 | C27: 44651 | D27: 20210401 | E27: 20220331 | F27: '002T0058D | G27: 2T58 TWO CAVITY WAX MOULD | H27: NO | I27: TLL | P27: 1 | R27: -1 | Z27: =IFERROR((O27+Q27)/(N27+P27),Y27/X27) -> 0
A28: 20300STR | B28: 44287 | C28: 44651 | D28: 20210401 | E28: 20220331 | F28: '003Y0026D | G28: 3Y26 SINGLE CAVITY WAX | H28: NO | I28: TLL | L28: 1 | M28: 115000 | N28: -1 | O28: -115000 | Z28: =IFERROR((O28+Q28)/(N28+P28),Y28/X28) -> 115000
A29: 20300STR | B29: 44287 | C29: 44651 | D29: 20210401 | E29: 20220331 | F29: '003Y0032 | G29: DISCONNECTOR CAM | H29: NO | I29: TRAD | L29: 158 | M29: 17854 | N29: -158 | O29: -17854 | Z29: =IFERROR((O29+Q29)/(N29+P29),Y29/X29) -> 113
A30: 20300STR | B30: 44287 | C30: 44651 | D30: 20210401 | E30: 20220331 | F30: '003Y0035 | G30: ISOLATER EYE BOLT | H30: NO | I30: TRAD | L30: 29 | M30: 5046 | N30: -29 | O30: -5046 | Z30: =IFERROR((O30+Q30)/(N30+P30),Y30/X30) -> 174
A31: 20300STR | B31: 44287 | C31: 44651 | D31: 20210401 | E31: 20220331 | F31: '003Y0042D | G31: 3Y42 FOUR CAVITY WAX INJECTION | H31: NO | I31: TLL | P31: 1 | Q31: 28000 | R31: -1 | S31: -28000 | Z31: =IFERROR((O31+Q31)/(N31+P31),Y31/X31) -> 28000
A32: 20300STR | B32: 44287 | C32: 44651 | D32: 20210401 | E32: 20220331 | F32: '007U0599D | G32: 7U599 TWO CAVITY WAX INJECTION | H32: NO | I32: TLL | L32: 1 | M32: 158000 | N32: -1 | O32: -158000 | P32: 1 | Q32: 158000 | R32: -1 | S32: -158000 | Z32: =IFERROR((O32+Q32)/(N32+P32),Y32/X32) -> #DIV/0!
A33: 20300STR | B33: 44287 | C33: 44651 | D33: 20210401 | E33: 20220331 | F33: '0101002 | G33: ALUMINIUM SCRAP | H33: KG | I33: RMFL | J33: 219.8 | K33: 25253.32 | L33: 1437.1 | M33: 312009.08 | N33: -1596.17 | O33: -322769.96 | P33: 2.38 | Q33: 582.5 | R33: -60 | S33: -14244.04 | X33: 3.11 | Y33: 830.9 | Z33: =IFERROR((O33+Q33)/(N33+P33),Y33/X33) -> 202.15176
A34: 20300STR | B34: 44287 | C34: 44651 | D34: 20210401 | E34: 20220331 | F34: '0101007 | G34: BISMUTH ( LOCAL ] | H34: KG | I34: RMFL | J34: 1.09 | K34: 1692.23 | X34: 1.09 | Y34: 1692.23 | Z34: =IFERROR((O34+Q34)/(N34+P34),Y34/X34) -> 1552.5046
A35: 20300STR | B35: 44287 | C35: 44651 | D35: 20210401 | E35: 20220331 | F35: '0101013 | G35: CHROMIUM ( INDIGENOUS ) | H35: KG | I35: RMFL | L35: 3700 | M35: 2681150 | N35: -3666.2 | O35: -2635669.9 | P35: 49.42 | Q35: 28891.55 | X35: 83.22 | Y35: 74371.64 | Z35: =IFERROR((O35+Q35)/(N35+P35),Y35/X35) -> 720.74562
A36: 20300STR | B36: 44287 | C36: 44651 | D36: 20210401 | E36: 20220331 | F36: '0101015 | G36: COBALT CATHODE- INDO NATIONAL | H36: KG | I36: RMFL | J36: 6.6 | K36: 18857.01 | L36: 80 | M36: 382200 | N36: -36.85 | O36: -146031.07 | P36: 3.2 | Q36: 11242.91 | X36: 52.95 | Y36: 266268.85 | Z36: =IFERROR((O36+Q36)/(N36+P36),Y36/X36) -> 4005.5917
A37: 20300STR | B37: 44287 | C37: 44651 | D37: 20210401 | E37: 20220331 | F37: '0101017 | G37: COPPER SCRAP ( RETURNS ) | H37: KG | I37: RMFR | J37: 220 | K37: 66213.4 | X37: 220 | Y37: 66213.4 | Z37: =IFERROR((O37+Q37)/(N37+P37),Y37/X37) -> 300.97
A38: 20300STR | B38: 44287 | C38: 44651 | D38: 20210401 | E38: 20220331 | F38: '0101019 | G38: COPPER SCRAP (PURCHASES) | H38: KG | I38: RMFL | J38: 139.88 | K38: 88124.77 | L38: 1145.6 | M38: 830917.16 | N38: -1272.25 | O38: -907571.67 | P38: 26.5 | Q38: 19118.58 | X38: 39.73 | Y38: 30588.84 | Z38: =IFERROR((O38+Q38)/(N38+P38),Y38/X38) -> 713.18731
A39: 20300STR | B39: 44287 | C39: 44651 | D39: 20210401 | E39: 20220331 | F39: '0101021 | G39: FERRO SILICO CALCIUM | H39: KG | I39: RMFL | J39: 65.48 | K39: 8376.49 | L39: 7920 | M39: 2137751 | N39: -6976.606 | O39: -1830116 | P39: 10.026 | Q39: 3325.95 | R39: -201 | S39: -46597.64 | X39: 817.9 | Y39: 272739.76 | Z39: =IFERROR((O39+Q39)/(N39+P39),Y39/X39) -> 262.22194
A40: 20300STR | B40: 44287 | C40: 44651 | D40: 20210401 | E40: 20220331 | F40: '0101059 | G40: MANGANESE METAL | H40: KG | I40: RMFL | J40: 793.92 | K40: 165873.47 | L40: 5578.608 | M40: 2328028.6 | N40: -5724.139 | O40: -2189016.7 | P40: 42.944 | Q40: 18349.55 | V40: -300 | W40: -110668.73 | X40: 391.333 | Y40: 212566.19 | Z40: =IFERROR((O40+Q40)/(N40+P40),Y40/X40) -> 382.07932
...

Sheet Mn Ledger
I1: B/p GL | J1: Opening Stock | K1: Opening Stock | L1: RECEIPT | M1: RECEIPT | N1: SIR | O1: SIR | P1: IGR | Q1: IGR | R1: SALES | S1: SALES | T1: TRASNFER | U1: TRASNFER | V1: Other Tran | W1: Other Tran | X1: Closing Stock | Y1: Closing Stock
A2: Branch Plant | B2: From Date | C2: To Date | D2: From Date | E2: To Date | F2: Item Code | G2: Description | H2: UOM | I2: Code | J2: Qty | K2: Amount | L2: Qty | M2: Amount | N2: Qty | O2: Amount | P2: Qty | Q2: Amount | R2: Qty | S2: Amount | T2: Qty | U2: Amount | V2: Qty | W2: Amount | X2: Qty | Y2: Amount | Z2: Rate
A3: 20200STR | B3: 44287 | C3: 44651 | D3: 20210401 | E3: 20220331 | F3: '001T0128D | G3: 1T128 FOUR CAVITY WAX INJ. | H3: NO | I3: TLL | L3: 1 | M3: 70000 | N3: -1 | O3: -70000 | Z3: =IFERROR((O3+Q3)/(N3+P3),Y3/X3) -> 70000
A4: 20200STR | B4: 44287 | C4: 44651 | D4: 20210401 | E4: 20220331 | F4: '001T0155D | G4: 1T155 FOUR CAVITY WAX INJE. | H4: NO | I4: TLL | L4: 1 | M4: 110000 | N4: -1 | O4: -110000 | Z4: =IFERROR((O4+Q4)/(N4+P4),Y4/X4) -> 110000
A5: 20200STR | B5: 44287 | C5: 44651 | D5: 20210401 | E5: 20220331 | F5: '001T0156D | G5: 1T156 FOUR CAVITY WAX MOULD | H5: NO | I5: TLL | L5: 1 | M5: 80000 | N5: -1 | O5: -80000 | Z5: =IFERROR((O5+Q5)/(N5+P5),Y5/X5) -> 80000
A6: 20200STR | B6: 44287 | C6: 44651 | D6: 20210401 | E6: 20220331 | F6: '001T0162D | G6: 1T162 FOUR CAVITY WAX INJE. | H6: NO | I6: TLL | L6: 1 | M6: 1 | N6: -1 | O6: -1 | P6: 1 | Q6: 110000 | R6: -1 | S6: -110000 | Z6: =IFERROR((O6+Q6)/(N6+P6),Y6/X6) -> #DIV/0!
A7: 20200STR | B7: 44287 | C7: 44651 | D7: 20210401 | E7: 20220331 | F7: '001T0165D | G7: 1T165/138 TWO CAVITY WAX INJ. | H7: NO | I7: TLL | L7: 1 | M7: 80000 | N7: -1 | O7: -80000 | Z7: =IFERROR((O7+Q7)/(N7+P7),Y7/X7) -> 80000
A8: 20200STR | B8: 44287 | C8: 44651 | D8: 20210401 | E8: 20220331 | F8: '001T0199D | G8: 1T199 TWO CAVITY WAX INJECTION | H8: NO | I8: TLL | L8: 1 | M8: 120000 | N8: -1 | O8: -120000 | Z8: =IFERROR((O8+Q8)/(N8+P8),Y8/X8) -> 120000
A9: 20200STR | B9: 44287 | C9: 44651 | D9: 20210401 | E9: 20220331 | F9: '001T0200D | G9: 1T200 TWO CAVITY WAX INJ. DIE | H9: NO | I9: TLL | L9: 1 | M9: 120000 | N9: -1 | O9: -120000 | Z9: =IFERROR((O9+Q9)/(N9+P9),Y9/X9) -> 120000
A10: 20200STR | B10: 44287 | C10: 44651 | D10: 20210401 | E10: 20220331 | F10: '001T0203D | G10: 1T203 TWO CAVITY WAX INJECTION | H10: NO | I10: TLL | L10: 1 | M10: 1 | N10: -1 | O10: -1 | Z10: =IFERROR((O10+Q10)/(N10+P10),Y10/X10) -> 1
A11: 20200STR | B11: 44287 | C11: 44651 | D11: 20210401 | E11: 20220331 | F11: '001T0204D | G11: 1T204 TWO CAVITY WAX INJECTION | H11: NO | I11: TLL | L11: 1 | M11: 1 | N11: -1 | O11: -1 | Z11: =IFERROR((O11+Q11)/(N11+P11),Y11/X11) -> 1
A12: 20200STR | B12: 44287 | C12: 44651 | D12: 20210401 | E12: 20220331 | F12: '001T0205D | G12: 1T205 TWO CAVITY WAX INJECTION | H12: NO | I12: TLL | L12: 1 | M12: 1 | N12: -1 | O12: -1 | Z12: =IFERROR((O12+Q12)/(N12+P12),Y12/X12) -> 1
A13: 20200STR | B13: 44287 | C13: 44651 | D13: 20210401 | E13: 20220331 | F13: '001T0210D | G13: 1T210 SINGLE CAVITY WAX INJ. | H13: NO | I13: TLL | L13: 1 | M13: 140000 | N13: -1 | O13: -140000 | Z13: =IFERROR((O13+Q13)/(N13+P13),Y13/X13) -> 140000
A14: 20200STR | B14: 44287 | C14: 44651 | D14: 20210401 | E14: 20220331 | F14: '001T0210RD | G14: 1T210 RISER MOULD WITH | H14: NO | I14: TLL | L14: 1 | M14: 50000 | N14: -1 | O14: -50000 | Z14: =IFERROR((O14+Q14)/(N14+P14),Y14/X14) -> 50000
A15: 20200STR | B15: 44287 | C15: 44651 | D15: 20210401 | E15: 20220331 | F15: '001T0213D | G15: 1T213 TWO CAVITY WAX INJECTION | H15: NO | I15: TLL | L15: 1 | M15: 1 | N15: -1 | O15: -1 | Z15: =IFERROR((O15+Q15)/(N15+P15),Y15/X15) -> 1
A16: 20200STR | B16: 44287 | C16: 44651 | D16: 20210401 | E16: 20220331 | F16: '001T0214D | G16: 1T214 TWO CAVITY WAX INJECTION | H16: NO | I16: TLL | L16: 1 | M16: 90000 | N16: -1 | O16: -90000 | Z16: =IFERROR((O16+Q16)/(N16+P16),Y16/X16) -> 90000
A17: 20200STR | B17: 44287 | C17: 44651 | D17: 20210401 | E17: 20220331 | F17: '002T0040D | G17: 2T40 MAIN DIE | H17: NO | I17: TLL | L17: 1 | M17: 80000 | N17: -1 | O17: -80000 | Z17: =IFERROR((O17+Q17)/(N17+P17),Y17/X17) -> 80000
A18: 20200STR | B18: 44287 | C18: 44651 | D18: 20210401 | E18: 20220331 | F18: '002T0052D | G18: 2T52 TWO CAVITY WAX MOULD | H18: NO | I18: TLL | L18: 1 | M18: 70000 | N18: -1 | O18: -70000 | Z18: =IFERROR((O18+Q18)/(N18+P18),Y18/X18) -> 70000
... A27: 20200STR | B27: 44287 | C27: 44651 | D27: 20210401 | E27: 20220331 | F27: '007U0599D | G27: 7U599 TWO CAVITY WAX INJECTION | H27: NO | I27: TLL | L27: 1 | M27: 1 | N27: -1 | O27: -1 | Z27: =IFERROR((O27+Q27)/(N27+P27),Y27/X27) -> 1
A28: 20200STR | B28: 44287 | C28: 44651 | D28: 20210401 | E28: 20220331 | F28: '0101001 | G28: ALUMINIUM PLATES & FLATS | H28: KG | I28: RMTL | J28: 11.5 | K28: 3449.64 | P28: 0.39 | Q28: 116.99 | X28: 11.89 | Y28: 3566.63 | Z28: =IFERROR((O28+Q28)/(N28+P28),Y28/X28) -> 299.97436
A29: 20200STR | B29: 44287 | C29: 44651 | D29: 20210401 | E29: 20220331 | F29: '0101002 | G29: ALUMINIUM SCRAP | H29: KG | I29: RMFL | J29: 76.3 | K29: 12566.59 | L29: 1105 | M29: 236494.75 | N29: -1391.07 | O29: -296951.27 | P29: 211.855 | Q29: 48449.6 | X29: 2.085 | Y29: 559.67 | Z29: =IFERROR((O29+Q29)/(N29+P29),Y29/X29) -> 210.73483
A30: 20200STR | B30: 44287 | C30: 44651 | D30: 20210401 | E30: 20220331 | F30: '0101013 | G30: CHROMIUM ( INDIGENOUS ) | H30: KG | I30: RMFL | J30: 4.65 | K30: 4464 | X30: 4.65 | Y30: 4464 | Z30: =IFERROR((O30+Q30)/(N30+P30),Y30/X30) -> 960
A31: 20200STR | B31: 44287 | C31: 44651 | D31: 20210401 | E31: 20220331 | F31: '0101017 | G31: COPPER SCRAP ( RETURNS ) | H31: KG | I31: RMFR | J31: 930 | K31: 121727.71 | P31: 19.44 | Q31: 2544.5 | R31: -934 | S31: -122251.26 | X31: 15.44 | Y31: 2020.95 | Z31: =IFERROR((O31+Q31)/(N31+P31),Y31/X31) -> 130.88992
A32: 20200STR | B32: 44287 | C32: 44651 | D32: 20210401 | E32: 20220331 | F32: '0101018 | G32: CUPRO MANG INGOTS 70:30(P&R) | H32: KG | I32: RMFL | J32: 28.4 | K32: 2942.8 | X32: 28.4 | Y32: 2942.8 | Z32: =IFERROR((O32+Q32)/(N32+P32),Y32/X32) -> 103.61972
A33: 20200STR | B33: 44287 | C33: 44651 | D33: 20210401 | E33: 20220331 | F33: '0101021 | G33: FERRO SILICO CALCIUM | H33: KG | I33: RMFL | J33: 144 | K33: 19185.76 | L33: 3794 | M33: 1004339.8 | N33: -3976.56 | O33: -1019941.7 | P33: 116.06 | Q33: 21959.44 | X33: 77.5 | Y33: 25543.35 | Z33: =IFERROR((O33+Q33)/(N33+P33),Y33/X33) -> 258.51114
A34: 20200STR | B34: 44287 | C34: 44651 | D34: 20210401 | E34: 20220331 | F34: '0101066 | G34: NICKEL BRIQUTTIES LOCAL | H34: KG | I34: RMFL | J34: 672.145 | K34: 881156.44 | L34: 2330 | M34: 3450714.6 | N34: -3059.21 | O34: -4413069.4 | P34: 55.455 | Q34: 83241.37 | V34: 40 | W34: 68146.21 | X34: 38.39 | Y34: 70189.29 | Z34: =IFERROR((O34+Q34)/(N34+P34),Y34/X34) -> 1441.4718
A35: 20200STR | B35: 44287 | C35: 44651 | D35: 20210401 | E35: 20220331 | F35: '0101068 | G35: NICKEL 4"X4" | H35: KG | I35: RMFL | L35: 100 | M35: 167500 | N35: -100 | O35: -167500.01 | Y35: -0.01 | Z35: =IFERROR((O35+Q35)/(N35+P35),Y35/X35) -> 1675.0001
A36: 20200STR | B36: 44287 | C36: 44651 | D36: 20210401 | E36: 20220331 | F36: '0101071 | G36: NICKEL CATHODE 1"X1" SQUARE | H36: KG | I36: RMFL | L36: 740 | M36: 1230101.3 | N36: -700.81 | O36: -1169849.5 | P36: 0.81 | Q36: 1346.1 | V36: -40 | W36: -61597.92 | Y36: -0.04 | Z36: =IFERROR((O36+Q36)/(N36+P36),Y36/X36) -> 1669.2906
A37: 20200STR | B37: 44287 | C37: 44651 | D37: 20210401 | E37: 20220331 | F37: '0101093 | G37: PURE TUNGSTON | H37: KG | I37: RMFL | J37: 4.31 | K37: 9427.7 | X37: 4.31 | Y37: 9427.7 | Z37: =IFERROR((O37+Q37)/(N37+P37),Y37/X37) -> 2187.4014
A38: 20200STR | B38: 44287 | C38: 44651 | D38: 20210401 | E38: 20220331 | F38: '0101094 | G38: TUNGSTON CARBIDE SCRAP | H38: KG | I38: RMFL | J38: 91 | K38: 10373.94 | X38: 91 | Y38: 10373.94 | Z38: =IFERROR((O38+Q38)/(N38+P38),Y38/X38) -> 113.99934
A39: 20200STR | B39: 44287 | C39: 44651 | D39: 20210401 | E39: 20220331 | F39: '0101187 | G39: ALUMINIUM PLATE | H39: KG | I39: STSL | L39: 27 | M39: 9450 | N39: -27 | O39: -9450 | Z39: =IFERROR((O39+Q39)/(N39+P39),Y39/X39) -> 350
A40: 20200STR | B40: 44287 | C40: 44651 | D40: 20210401 | E40: 20220331 | F40: '0102017 | G40: FERRO CHROME L.C. 0.1C | H40: KG | I40: RMFL | J40: 1538.18 | K40: 256001.9 | L40: 10537 | M40: 2475382.5 | N40: -11594.31 | O40: -2580553.5 | P40: 132.955 | Q40: 25167.32 | R40: -1 | S40: -172.54 | X40: 612.825 | Y40: 175825.64 | Z40: =IFERROR((O40+Q40)/(N40+P40),Y40/X40) -> 222.95673
A41: 20200STR | B41: 44287 | C41: 44651 | D41: 20210401 | E41: 20220331 | F41: '0102034 | G41: IRON SULPHIDE | H41: KG | I41: RMFL | J41: 46.6 | K41: 1431.82 | L41: 133 | M41: 4209.04 | N41: -155.4 | O41: -4920.92 | P41: 0.72 | Q41: 22.48 | R41: -1 | S41: -34.81 | X41: 23.92 | Y41: 707.61 | Z41: =IFERROR((O41+Q41)/(N41+P41),Y41/X41) -> 31.668218
A42: 20200STR | B42: 44287 | C42: 44651 | D42: 20210401 | E42: 20220331 | F42: '0102045 | G42: SILICO MN | H42: KG | I42: RMFL | J42: 92.99 | K42: 5872.22 | L42: 3850 | M42: 368450 | N42: -3960.066 | O42: -375767.5 | P42: 41.85 | Q42: 3685.79 | X42: 24.774 | Y42: 2240.51 | Z42: =IFERROR((O42+Q42)/(N42+P42),Y42/X42) -> 94.962021
A43: 20200STR | B43: 44287 | C43: 44651 | D43: 20210401 | E43: 20220331 | F43: '0102048 | G43: FERRO MOLYBDENUM | H43: KG | I43: RMFL | J43: 183.218 | K43: 249411.84 | L43: 745 | M43: 1450946.2 | N43: -918.773 | O43: -1665109.9 | P43: 9.937 | Q43: 16850.27 | X43: 19.382 | Y43: 52098.43 | Z43: =IFERROR((O43+Q43)/(N43+P43),Y43/X43) -> 1813.5941
A44: 20200STR | B44: 44287 | C44: 44651 | D44: 20210401 | E44: 20220331 | F44: '0102049 | G44: HIGH CARBON FERRO MANGANES | H44: KG | I44: RMFL | J44: 300.526 | K44: 18922.12 | L44: 6050 | M44: 603400 | N44: -6047.806 | O44: -592072.39 | P44: 105.85 | Q44: 11485.62 | R44: -150 | S44: -15252.64 | X44: 258.57 | Y44: 26482.71 | Z44: =IFERROR((O44+Q44)/(N44+P44),Y44/X44) -> 97.709705
A45: 20200STR | B45: 44287 | C45: 44651 | D45: 20210401 | E45: 20220331 | F45: '0102074 | G45: FERRO SILICON | H45: KG | I45: RMFL | J45: 468.705 | K45: 51936.72 | L45: 5117 | M45: 868840.99 | N45: -5603.43 | O45: -923038.63 | P45: 104.225 | Q45: 21148.07 | X45: 86.5 | Y45: 18887.15 | Z45: =IFERROR((O45+Q45)/(N45+P45),Y45/X45) -> 164.00381
A46: 20200STR | B46: 44287 | C46: 44651 | D46: 20210401 | E46: 20220331 | F46: '0102084 | G46: FERRO TITANIUM | H46: KG | I46: RMFL | J46: 24.8 | K46: 1543.3 | X46: 24.8 | Y46: 1543.3 | Z46: =IFERROR((O46+Q46)/(N46+P46),Y46/X46) -> 62.229839
A47: 20200STR | B47: 44287 | C47: 44651 | D47: 20210401 | E47: 20220331 | F47: '0102088 | G47: TUNGSTON NICKEL (PUR. & RET.) | H47: KG | I47: RMFL | J47: 68.5 | K47: 115418.39 | N47: -61.6 | O47: -104839.36 | X47: 6.9 | Y47: 10579.03 | Z47: =IFERROR((O47+Q47)/(N47+P47),Y47/X47) -> 1701.9377
A48: 20200STR | B48: 44287 | C48: 44651 | D48: 20210401 | E48: 20220331 | F48: '0102093 | G48: FERRO VANADIUM | H48: KG | I48: RMFL | J48: 0.17 | K48: 330.98 | X48: 0.17 | Y48: 330.98 | Z48: =IFERROR((O48+Q48)/(N48+P48),Y48/X48) -> 1946.9412
...
